Traceback (most recent call last):
  File "/home/desktop-ubuntu/anaconda3/envs/rs_survey_tensorflow1/lib/python3.7/site-packages/tensorflow_core/python/client/session.py", line 1365, in _do_call
    return fn(*args)
  File "/home/desktop-ubuntu/anaconda3/envs/rs_survey_tensorflow1/lib/python3.7/site-packages/tensorflow_core/python/client/session.py", line 1350, in _run_fn
    target_list, run_metadata)
  File "/home/desktop-ubuntu/anaconda3/envs/rs_survey_tensorflow1/lib/python3.7/site-packages/tensorflow_core/python/client/session.py", line 1443, in _call_tf_sessionrun
    run_metadata)
tensorflow.python.framework.errors_impl.InvalidArgumentError: indices[13813668] = 138493 is not in [0, 138493)
         [[{{node embedding_lookup}}]]

During handling of the above exception, another exception occurred:

Traceback (most recent call last):
  File "main.py", line 135, in <module>
    rec = Recommender(args)
  File "/home/desktop-ubuntu/Git/RL_RS_Survey/KGQR/src/recommender.py", line 32, in __init__
    self.env = Env(episode_length=self.episode_length,alpha=self.alpha, boundary_rating = self.boundary_rating, max_rating=self.max_rating ,min_rating=self.min_rating, ratingfile=self.dataset)
  File "/home/desktop-ubuntu/Git/RL_RS_Survey/KGQR/src/env.py", line 32, in __init__
    utils.get_envobjects(ratingfile=ratingfile)
  File "/home/desktop-ubuntu/Git/RL_RS_Survey/KGQR/src/utils.py", line 80, in get_envobjects
    ys: np.float32(dtrain[:, 2])})
  File "/home/desktop-ubuntu/anaconda3/envs/rs_survey_tensorflow1/lib/python3.7/site-packages/tensorflow_core/python/client/session.py", line 956, in run
    run_metadata_ptr)
  File "/home/desktop-ubuntu/anaconda3/envs/rs_survey_tensorflow1/lib/python3.7/site-packages/tensorflow_core/python/client/session.py", line 1180, in _run
    feed_dict_tensor, options, run_metadata)
  File "/home/desktop-ubuntu/anaconda3/envs/rs_survey_tensorflow1/lib/python3.7/site-packages/tensorflow_core/python/client/session.py", line 1359, in _do_run
    run_metadata)
  File "/home/desktop-ubuntu/anaconda3/envs/rs_survey_tensorflow1/lib/python3.7/site-packages/tensorflow_core/python/client/session.py", line 1384, in _do_call
    raise type(e)(node_def, op, message)
tensorflow.python.framework.errors_impl.InvalidArgumentError: indices[13813668] = 138493 is not in [0, 138493)
         [[node embedding_lookup (defined at /home/desktop-ubuntu/anaconda3/envs/rs_survey_tensorflow1/lib/python3.7/site-packages/tensorflow_core/python/framework/ops.py:1748) ]]

Original stack trace for 'embedding_lookup':
  File "main.py", line 135, in <module>
    rec = Recommender(args)
  File "/home/desktop-ubuntu/Git/RL_RS_Survey/KGQR/src/recommender.py", line 32, in __init__
    self.env = Env(episode_length=self.episode_length,alpha=self.alpha, boundary_rating = self.boundary_rating, max_rating=self.max_rating ,min_rating=self.min_rating, ratingfile=self.dataset)
  File "/home/desktop-ubuntu/Git/RL_RS_Survey/KGQR/src/env.py", line 32, in __init__
    utils.get_envobjects(ratingfile=ratingfile)
  File "/home/desktop-ubuntu/Git/RL_RS_Survey/KGQR/src/utils.py", line 61, in get_envobjects
    user_embs = tf.nn.embedding_lookup(user_embeddings, user_ids)
  File "/home/desktop-ubuntu/anaconda3/envs/rs_survey_tensorflow1/lib/python3.7/site-packages/tensorflow_core/python/ops/embedding_ops.py", line 317, in embedding_lookup
    transform_fn=None)
  File "/home/desktop-ubuntu/anaconda3/envs/rs_survey_tensorflow1/lib/python3.7/site-packages/tensorflow_core/python/ops/embedding_ops.py", line 135, in _embedding_lookup_and_transform
    array_ops.gather(params[0], ids, name=name), ids, max_norm)
  File "/home/desktop-ubuntu/anaconda3/envs/rs_survey_tensorflow1/lib/python3.7/site-packages/tensorflow_core/python/util/dispatch.py", line 180, in wrapper
    return target(*args, **kwargs)
  File "/home/desktop-ubuntu/anaconda3/envs/rs_survey_tensorflow1/lib/python3.7/site-packages/tensorflow_core/python/ops/array_ops.py", line 3956, in gather
    params, indices, axis, name=name)
  File "/home/desktop-ubuntu/anaconda3/envs/rs_survey_tensorflow1/lib/python3.7/site-packages/tensorflow_core/python/ops/gen_array_ops.py", line 4082, in gather_v2
    batch_dims=batch_dims, name=name)
  File "/home/desktop-ubuntu/anaconda3/envs/rs_survey_tensorflow1/lib/python3.7/site-packages/tensorflow_core/python/framework/op_def_library.py", line 794, in _apply_op_helper
    op_def=op_def)
  File "/home/desktop-ubuntu/anaconda3/envs/rs_survey_tensorflow1/lib/python3.7/site-packages/tensorflow_core/python/util/deprecation.py", line 507, in new_func
    return func(*args, **kwargs)
  File "/home/desktop-ubuntu/anaconda3/envs/rs_survey_tensorflow1/lib/python3.7/site-packages/tensorflow_core/python/framework/ops.py", line 3357, in create_op
    attrs, op_def, compute_device)
  File "/home/desktop-ubuntu/anaconda3/envs/rs_survey_tensorflow1/lib/python3.7/site-packages/tensorflow_core/python/framework/ops.py", line 3426, in _create_op_internal
    op_def=op_def)
  File "/home/desktop-ubuntu/anaconda3/envs/rs_survey_tensorflow1/lib/python3.7/site-packages/tensorflow_core/python/framework/ops.py", line 1748, in __init__
    self._traceback = tf_stack.extract_stack()
